Traceback (most recent call last):
  File "C:\Users\NatSciTeaching\anaconda3\lib\site-packages\jupyter_cache\executors\utils.py", line 56, in single_nb_execution
    record_timing=False,
  File "C:\Users\NatSciTeaching\anaconda3\lib\site-packages\nbclient\client.py", line 1112, in execute
    return NotebookClient(nb=nb, resources=resources, km=km, **kwargs).execute()
  File "C:\Users\NatSciTeaching\anaconda3\lib\site-packages\nbclient\util.py", line 74, in wrapped
    return just_run(coro(*args, **kwargs))
  File "C:\Users\NatSciTeaching\anaconda3\lib\site-packages\nbclient\util.py", line 53, in just_run
    return loop.run_until_complete(coro)
  File "C:\Users\NatSciTeaching\anaconda3\lib\asyncio\base_events.py", line 587, in run_until_complete
    return future.result()
  File "C:\Users\NatSciTeaching\anaconda3\lib\site-packages\nbclient\client.py", line 554, in async_execute
    cell, index, execution_count=self.code_cells_executed + 1
  File "C:\Users\NatSciTeaching\anaconda3\lib\site-packages\nbclient\client.py", line 857, in async_execute_cell
    self._check_raise_for_error(cell, exec_reply)
  File "C:\Users\NatSciTeaching\anaconda3\lib\site-packages\nbclient\client.py", line 760, in _check_raise_for_error
    raise CellExecutionError.from_cell_and_msg(cell, exec_reply_content)
nbclient.exceptions.CellExecutionError: An error occurred while executing the following cell:
------------------
plt.imshow(sphere)

------------------

[1;31m---------------------------------------------------------------------------[0m
[1;31mNameError[0m                                 Traceback (most recent call last)
[1;32mC:\Users\NATSCI~1\AppData\Local\Temp/ipykernel_20136/4105552836.py[0m in [0;36m<module>[1;34m[0m
[1;32m----> 1[1;33m [0mplt[0m[1;33m.[0m[0mimshow[0m[1;33m([0m[0msphere[0m[1;33m)[0m[1;33m[0m[1;33m[0m[0m
[0m
[1;31mNameError[0m: name 'plt' is not defined
NameError: name 'plt' is not defined

