Traceback (most recent call last):
  File "c:\users\natsciteaching\appdata\local\programs\python\python37\lib\site-packages\jupyter_cache\executors\utils.py", line 56, in single_nb_execution
    record_timing=False,
  File "c:\users\natsciteaching\appdata\local\programs\python\python37\lib\site-packages\nbclient\client.py", line 1204, in execute
    return NotebookClient(nb=nb, resources=resources, km=km, **kwargs).execute()
  File "c:\users\natsciteaching\appdata\local\programs\python\python37\lib\site-packages\nbclient\util.py", line 84, in wrapped
    return just_run(coro(*args, **kwargs))
  File "c:\users\natsciteaching\appdata\local\programs\python\python37\lib\site-packages\nbclient\util.py", line 62, in just_run
    return loop.run_until_complete(coro)
  File "c:\users\natsciteaching\appdata\local\programs\python\python37\lib\asyncio\base_events.py", line 587, in run_until_complete
    return future.result()
  File "c:\users\natsciteaching\appdata\local\programs\python\python37\lib\site-packages\nbclient\client.py", line 664, in async_execute
    cell, index, execution_count=self.code_cells_executed + 1
  File "c:\users\natsciteaching\appdata\local\programs\python\python37\lib\site-packages\nbclient\client.py", line 965, in async_execute_cell
    await self._check_raise_for_error(cell, cell_index, exec_reply)
  File "c:\users\natsciteaching\appdata\local\programs\python\python37\lib\site-packages\nbclient\client.py", line 862, in _check_raise_for_error
    raise CellExecutionError.from_cell_and_msg(cell, exec_reply_content)
nbclient.exceptions.CellExecutionError: An error occurred while executing the following cell:
------------------
N = 200 # number of time steps
n = 20 # size of region
z = np.zeros((N, n, n))

z_init = np.zeros((n, n))

# set the inital concentrations

z_init[8:11,8:11] = 1

z[0,:,:] = z_init

for i in range(N-1):
    z[i+1,:,:] = smooth(z[i,:,:])
    # set z[i,:,:] to the value of the next moving average
    #plt.figure()
    #plt.imshow(z[i,:,:])


plt.figure()
plt.plot(z[:,5,5])


------------------

[1;31m---------------------------------------------------------------------------[0m
[1;31mNameError[0m                                 Traceback (most recent call last)
[1;32m~\AppData\Local\Temp\ipykernel_32240\747633008.py[0m in [0;36m<module>[1;34m[0m
[0;32m     12[0m [1;33m[0m[0m
[0;32m     13[0m [1;32mfor[0m [0mi[0m [1;32min[0m [0mrange[0m[1;33m([0m[0mN[0m[1;33m-[0m[1;36m1[0m[1;33m)[0m[1;33m:[0m[1;33m[0m[1;33m[0m[0m
[1;32m---> 14[1;33m     [0mz[0m[1;33m[[0m[0mi[0m[1;33m+[0m[1;36m1[0m[1;33m,[0m[1;33m:[0m[1;33m,[0m[1;33m:[0m[1;33m][0m [1;33m=[0m [0msmooth[0m[1;33m([0m[0mz[0m[1;33m[[0m[0mi[0m[1;33m,[0m[1;33m:[0m[1;33m,[0m[1;33m:[0m[1;33m][0m[1;33m)[0m[1;33m[0m[1;33m[0m[0m
[0m[0;32m     15[0m     [1;31m# set z[i,:,:] to the value of the next moving average[0m[1;33m[0m[1;33m[0m[1;33m[0m[0m
[0;32m     16[0m     [1;31m#plt.figure()[0m[1;33m[0m[1;33m[0m[1;33m[0m[0m

[1;31mNameError[0m: name 'smooth' is not defined
NameError: name 'smooth' is not defined

