Traceback (most recent call last):
  File "C:\Users\Ella Metcalfe\anaconda3\lib\site-packages\jupyter_cache\executors\utils.py", line 51, in single_nb_execution
    executenb(
  File "C:\Users\Ella Metcalfe\anaconda3\lib\site-packages\nbclient\client.py", line 1263, in execute
    return NotebookClient(nb=nb, resources=resources, km=km, **kwargs).execute()
  File "C:\Users\Ella Metcalfe\anaconda3\lib\site-packages\nbclient\util.py", line 85, in wrapped
    return just_run(coro(*args, **kwargs))
  File "C:\Users\Ella Metcalfe\anaconda3\lib\site-packages\nbclient\util.py", line 60, in just_run
    return loop.run_until_complete(coro)
  File "C:\Users\Ella Metcalfe\anaconda3\lib\asyncio\base_events.py", line 647, in run_until_complete
    return future.result()
  File "C:\Users\Ella Metcalfe\anaconda3\lib\site-packages\nbclient\client.py", line 701, in async_execute
    await self.async_execute_cell(
  File "C:\Users\Ella Metcalfe\anaconda3\lib\site-packages\nbclient\client.py", line 1019, in async_execute_cell
    await self._check_raise_for_error(cell, cell_index, exec_reply)
  File "C:\Users\Ella Metcalfe\anaconda3\lib\site-packages\nbclient\client.py", line 913, in _check_raise_for_error
    raise CellExecutionError.from_cell_and_msg(cell, exec_reply_content)
nbclient.exceptions.CellExecutionError: An error occurred while executing the following cell:
------------------
# Analytic function and derivative
f = lambda x: sin(x)+x
fp= lambda x: cos(x)+1 

# Apply finite difference formula
h=1e-3
xf,_,ydf=fdiff(f,[-pi,pi],h)
xm,_,ydm=cdiff(f,[-pi,pi],h)

#xm=xf+h/2         #midpoint x values
errf = ydf-fp(xf)  #error using forward estimate
errm = ydm-fp(xm)  #error using central estimate


plt.semilogy(xf,abs(errf),label='Forward difference')
plt.semilogy(xm,abs(errm),label='Central difference')
plt.legend()
plt.show()
------------------

[1;31m---------------------------------------------------------------------------[0m
[1;31mValueError[0m                                Traceback (most recent call last)
[1;32m~\AppData\Local\Temp\ipykernel_29548\2424435652.py[0m in [0;36m<cell line: 12>[1;34m()[0m
[0;32m     10[0m [1;31m#xm=xf+h/2         #midpoint x values[0m[1;33m[0m[1;33m[0m[0m
[0;32m     11[0m [0merrf[0m [1;33m=[0m [0mydf[0m[1;33m-[0m[0mfp[0m[1;33m([0m[0mxf[0m[1;33m)[0m  [1;31m#error using forward estimate[0m[1;33m[0m[1;33m[0m[0m
[1;32m---> 12[1;33m [0merrm[0m [1;33m=[0m [0mydm[0m[1;33m-[0m[0mfp[0m[1;33m([0m[0mxm[0m[1;33m)[0m  [1;31m#error using central estimate[0m[1;33m[0m[1;33m[0m[0m
[0m[0;32m     13[0m [1;33m[0m[0m
[0;32m     14[0m [1;33m[0m[0m

[1;31mValueError[0m: operands could not be broadcast together with shapes (6284,) (6285,) 
ValueError: operands could not be broadcast together with shapes (6284,) (6285,) 

