Traceback (most recent call last):
  File "C:\Users\Ella Metcalfe\anaconda3\lib\site-packages\jupyter_cache\executors\utils.py", line 51, in single_nb_execution
    executenb(
  File "C:\Users\Ella Metcalfe\anaconda3\lib\site-packages\nbclient\client.py", line 1263, in execute
    return NotebookClient(nb=nb, resources=resources, km=km, **kwargs).execute()
  File "C:\Users\Ella Metcalfe\anaconda3\lib\site-packages\nbclient\util.py", line 85, in wrapped
    return just_run(coro(*args, **kwargs))
  File "C:\Users\Ella Metcalfe\anaconda3\lib\site-packages\nbclient\util.py", line 60, in just_run
    return loop.run_until_complete(coro)
  File "C:\Users\Ella Metcalfe\anaconda3\lib\asyncio\base_events.py", line 647, in run_until_complete
    return future.result()
  File "C:\Users\Ella Metcalfe\anaconda3\lib\site-packages\nbclient\client.py", line 701, in async_execute
    await self.async_execute_cell(
  File "C:\Users\Ella Metcalfe\anaconda3\lib\site-packages\nbclient\client.py", line 1019, in async_execute_cell
    await self._check_raise_for_error(cell, cell_index, exec_reply)
  File "C:\Users\Ella Metcalfe\anaconda3\lib\site-packages\nbclient\client.py", line 913, in _check_raise_for_error
    raise CellExecutionError.from_cell_and_msg(cell, exec_reply_content)
nbclient.exceptions.CellExecutionError: An error occurred while executing the following cell:
------------------
from numpy import diag,ones,zeros,linalg

#---------------------------------------------------------------
# Construct tridiagonal matrix A and vector b
# Initially we ignore the BCs:

c1,c2,c3= [1-h, -2+10*h**2, 1+h]

A = diag([c1]*(n-1),k=-2) + \
    diag([c2]*n,    k=-1) + \
    diag([c3]*(n+1),k=0)

b = zeros((n+1,1))

# Now enforce the BCs: 
A[1,[0,1,2]], b[1] = [ 0,1,0], 1        # x(0)
A[0,[0,1,2]], b[0] = [-1,0,1], -2*h     # x'(0)

#---------------------------------------------------------------
# Solve the matrix system numerically
x= linalg.solve(A,b)

#remove fictitious end point and flatten
x = x[1:].flatten()                                   

# Compare to analytic solution
plt.plot(t,abs(x-xsol))
plt.xlabel('t'); plt.ylabel('Error')
plt.show()
------------------

[1;31m---------------------------------------------------------------------------[0m
[1;31mNameError[0m                                 Traceback (most recent call last)
[1;32m~\AppData\Local\Temp\ipykernel_32368\2230526223.py[0m in [0;36m<cell line: 27>[1;34m()[0m
[0;32m     25[0m [1;33m[0m[0m
[0;32m     26[0m [1;31m# Compare to analytic solution[0m[1;33m[0m[1;33m[0m[0m
[1;32m---> 27[1;33m [0mplt[0m[1;33m.[0m[0mplot[0m[1;33m([0m[0mt[0m[1;33m,[0m[0mabs[0m[1;33m([0m[0mx[0m[1;33m-[0m[0mxsol[0m[1;33m)[0m[1;33m)[0m[1;33m[0m[1;33m[0m[0m
[0m[0;32m     28[0m [0mplt[0m[1;33m.[0m[0mxlabel[0m[1;33m([0m[1;34m't'[0m[1;33m)[0m[1;33m;[0m [0mplt[0m[1;33m.[0m[0mylabel[0m[1;33m([0m[1;34m'Error'[0m[1;33m)[0m[1;33m[0m[1;33m[0m[0m
[0;32m     29[0m [0mplt[0m[1;33m.[0m[0mshow[0m[1;33m([0m[1;33m)[0m[1;33m[0m[1;33m[0m[0m

[1;31mNameError[0m: name 't' is not defined
NameError: name 't' is not defined

