Traceback (most recent call last):
  File "C:\Users\Ella Metcalfe\anaconda3\lib\site-packages\jupyter_cache\executors\utils.py", line 51, in single_nb_execution
    executenb(
  File "C:\Users\Ella Metcalfe\anaconda3\lib\site-packages\nbclient\client.py", line 1263, in execute
    return NotebookClient(nb=nb, resources=resources, km=km, **kwargs).execute()
  File "C:\Users\Ella Metcalfe\anaconda3\lib\site-packages\nbclient\util.py", line 85, in wrapped
    return just_run(coro(*args, **kwargs))
  File "C:\Users\Ella Metcalfe\anaconda3\lib\site-packages\nbclient\util.py", line 60, in just_run
    return loop.run_until_complete(coro)
  File "C:\Users\Ella Metcalfe\anaconda3\lib\asyncio\base_events.py", line 647, in run_until_complete
    return future.result()
  File "C:\Users\Ella Metcalfe\anaconda3\lib\site-packages\nbclient\client.py", line 701, in async_execute
    await self.async_execute_cell(
  File "C:\Users\Ella Metcalfe\anaconda3\lib\site-packages\nbclient\client.py", line 1019, in async_execute_cell
    await self._check_raise_for_error(cell, cell_index, exec_reply)
  File "C:\Users\Ella Metcalfe\anaconda3\lib\site-packages\nbclient\client.py", line 913, in _check_raise_for_error
    raise CellExecutionError.from_cell_and_msg(cell, exec_reply_content)
nbclient.exceptions.CellExecutionError: An error occurred while executing the following cell:
------------------
a = -np.pi
b = np.pi
x = np.linspace(a,b,100)
h = x[1]-x[0]
print('Step size h= {:.5f}'.format(h))

# Forward difference rule
xx = np.append(x, (b+h, b+2*h))
y = np.sin(xx) + xx
d2ydx2_fwd = (y[:-2]-2*y[1:-1]+y[2:])/h**2

exact = -np.sin(x)

plt.plot(x, np.abs(d2ydx2_fwd-exact))
plt.xlabel("x")
plt.ylabel("error")
plt.title("forward difference")
plt.show()

# Central difference rule
xx = np.insert(x, [0,len(x)], [a-h,b+h])
y = np.sin(xx) + xx
d2ydx2_ctr = (y[:-2]-2*y[1:-1]+y[2:])/h**2

plt.plot(x, np.abs(d2ydx2_ctr-exact))
plt.xlabel("x")
plt.ylabel("error")
plt.title("central difference")
plt.show()
------------------

[1;31m---------------------------------------------------------------------------[0m
[1;31mNameError[0m                                 Traceback (most recent call last)
[1;32m~\AppData\Local\Temp\ipykernel_26504\2009448772.py[0m in [0;36m<cell line: 1>[1;34m()[0m
[1;32m----> 1[1;33m [0ma[0m [1;33m=[0m [1;33m-[0m[0mnp[0m[1;33m.[0m[0mpi[0m[1;33m[0m[1;33m[0m[0m
[0m[0;32m      2[0m [0mb[0m [1;33m=[0m [0mnp[0m[1;33m.[0m[0mpi[0m[1;33m[0m[1;33m[0m[0m
[0;32m      3[0m [0mx[0m [1;33m=[0m [0mnp[0m[1;33m.[0m[0mlinspace[0m[1;33m([0m[0ma[0m[1;33m,[0m[0mb[0m[1;33m,[0m[1;36m100[0m[1;33m)[0m[1;33m[0m[1;33m[0m[0m
[0;32m      4[0m [0mh[0m [1;33m=[0m [0mx[0m[1;33m[[0m[1;36m1[0m[1;33m][0m[1;33m-[0m[0mx[0m[1;33m[[0m[1;36m0[0m[1;33m][0m[1;33m[0m[1;33m[0m[0m
[0;32m      5[0m [0mprint[0m[1;33m([0m[1;34m'Step size h= {:.5f}'[0m[1;33m.[0m[0mformat[0m[1;33m([0m[0mh[0m[1;33m)[0m[1;33m)[0m[1;33m[0m[1;33m[0m[0m

[1;31mNameError[0m: name 'np' is not defined
NameError: name 'np' is not defined

